Workbook

Sheet 部门绩效考核
A1: 2025年9月部门考核评定汇总表
M2: 46085
A3: 部门 | B3: 物业分公司 | C3: 总经理助理 | D3: 高新分公司 | E3: 综合办公室 | F3: 投资拓展部 | G3: 项目管理部 | H3: 设计管理部 | I3: 财务部 | J3: 党群纪检 审计部 | K3: 造价合约部 | L3: 质量安全部 | M3: 资产管理部
A4: 部门排名 | B4: 5 | C4: 1 | D4: 3 | E4: 2 | F4: 6 | G4: 9 | H4: 8 | I4: 10 | J4: 7 | K4: 11 | L4: 12 | M4: 4
A5: 得分 | B5: 86.79 | C5: 89.33 | D5: 88.04 | E5: 89.2 | F5: 85.44 | G5: 84.44 | H5: 84.9 | I5: 84.37 | J5: 85.02 | K5: 84.2 | L5: 83.16 | M5: 86.91
A6: 本月部门 综合评定结果 | B6: B | C6: A | D6: B | E6: B | F6: B | G6: B | H6: B | I6: B | J6: B | K6: B | L6: B | M6: B
A7: 部门负责人 | B7: 陈朝炜 | C7: 张云旭 | D7: 郑石斌 | E7: 吴华珊 | F7: 张旻菲 | G7: / | H7: 刘德清 | I7: 陈玲巧 | J7: 龚心怡 | K7: / | L7: 朱晓东 | M7: 叶 炫
A8: 本月部门负责人 综合评定结果
A9: 1月部门 综合评定结果 | B9: A | C9: B | D9: B | E9: B | F9: B | G9: B | H9: B | I9: B | J9: B | K9: B | L9: B | M9: B
A10: 备注：1、部门负责人等级与部门考核等级相同。 2、月度优秀不超过总数的30%

Sheet 部门副职考核
A1: 2025年9月中层副职管理人员考核评定汇总表
G2: 46085
A3: 部门 | B3: 物业分公司 | C3: 高新分公司 | D3: 综合办公室 | E3: 投资拓展部 | F3: 项目管理部 | G3: 造价合约部
A4: 副职管理人员 | B4: 陈媛 | C4: 孙安娜 | D4: 胡彩仙 | E4: 陈晔龙 | F4: 蔡震空 | G4: 陈 杰
A5: 部门考核得分 | B5: =部门绩效考核!B5 | C5: =部门绩效考核!D5 | D5: =部门绩效考核!E5 | E5: =部门绩效考核!F5 | F5: =部门绩效考核!G5 | G5: =部门绩效考核!K5
A6: 部门考核等级 | B6: =_xlfn.IFS(部门绩效考核!B6="A","95",部门绩效考核!B6="B","80",部门绩效考核!B6="C","65",部门绩效考核!B6="D","50") | C6: =_xlfn.IFS(部门绩效考核!D6="A","95",部门绩效考核!D6="B","80",部门绩效考核!D6="C","65",部门绩效考核!D6="D","50") | D6: =_xlfn.IFS(部门绩效考核!E6="A","95",部门绩效考核!E6="B","80",部门绩效考核!E6="C","65",部门绩效考核!E6="D","50") | E6: =_xlfn.IFS(部门绩效考核!F6="A","95",部门绩效考核!F6="B","80",部门绩效考核!F6="C","65",部门绩效考核!F6="D","50") | F6: =_xlfn.IFS(部门绩效考核!G6="A","95",部门绩效考核!G6="B","80",部门绩效考核!G6="C","65",部门绩效考核!G6="D","50") | G6: =_xlfn.IFS(部门绩效考核!K6="A","95",部门绩效考核!K6="B","80",部门绩效考核!K6="C","65",部门绩效考核!K6="D","50")
A7: 部门负责人评分 | B7: 88 | C7: 89 | D7: 91 | E7: 89 | F7: 89 | G7: 90
A8: 分管领导评分 | B8: 89 | C8: 89 | D8: 89 | E8: 89 | F8: 90 | G8: 89
A9: 综合得分 | B9: 94.39 | C9: 87.87 | D9: 84.41 | E9: 84.25 | F9: 83.23 | G9: 83.92
A10: 参照部门得分的 综合得分 | B10: =ROUND(B5*0.5+B7*0.2+B8*0.3,2) | C10: =ROUND(C5*0.5+C7*0.2+C8*0.3,2) | D10: =ROUND(D5*0.5+D7*0.2+D8*0.3,2) | E10: =ROUND(E5*0.5+E7*0.2+E8*0.3,2) | F10: =ROUND(F5*0.5+F7*0.2+F8*0.3,2) | G10: =ROUND(G5*0.5+G7*0.2+G8*0.3,2)
A11: 排 名 | B11: 1 | C11: 5 | D11: 2 | E11: 5 | F11: 3 | G11: 4
A12: 本月综合评定结果 | B12: A | C12: B | D12: B | E12: B | F12: B | G12: B
A13: 1月综合评定结果 | B13: B | C13: B | D13: B | E13: B | F13: B | G13: B
A14: 备注：1、副职管理人员月度优秀比例不超过30%

Sheet 绩效考评汇总表
A1: 2025年9月绩效考核评定汇总表
K2: 46085
A3: 部门 | B3: 部门负责人 | C3: 部门排名 | D3: 得分 | E3: 部门考核结果 | F3: 序号 | G3: 员工姓名 | H3: 排名 | I3: 得分 | J3: 9月员工 综合评定结果 | K3: 1月员工 综合评定结果 | L3: 部门 | M3: 领导
A4: 物业分公司 | B4: =部门绩效考核!B7 | C4: =部门绩效考核!B4 | D4: =部门绩效考核!B5 | E4: =部门绩效考核!B6 | F4: =ROW()-3 | G4: 林晓燕 | H4: 1 | I4: 88.23 | J4: B | K4: A | L4: 89 | M4: 90
F5: =ROW()-3 | G5: 林小森 | H5: 2 | I5: 88.84 | J5: A | K5: A | L5: 88 | M5: 89
F6: =ROW()-3 | G6: 林大江 | H6: 3 | I6: 86.23 | J6: B | K6: B | L6: 86 | M6: 87
F7: =ROW()-3 | G7: 钱 源 | H7: 3 | I7: 87.19 | J7: B | K7: B | L7: 86 | M7: 87
F8: =ROW()-3 | G8: 王子妍 | H8: 5 | I8: 87.94 | J8: B | K8: B | L8: 85 | M8: 86
F9: =ROW()-3 | G9: 肖炜萍 | H9: 6 | I9: 86.01 | J9: B | K9: C | L9: 84 | M9: 85
A10: 总经理助理 | B10: 张云旭 | C10: =部门绩效考核!C4 | D10: =部门绩效考核!C5 | E10: =部门绩效考核!C6
A11: 高新区分公司 | B11: =部门绩效考核!D7 | C11: =部门绩效考核!D4 | D11: =部门绩效考核!D5 | E11: =部门绩效考核!D6 | F11: =ROW()-3 | G11: 高 彬 | H11: 1 | I11: 90.62 | J11: A | K11: B | L11: 90 | M11: 90
F12: =ROW()-3 | G12: 陈南钟 | H12: 2 | I12: 85.16 | J12: B | K12: B | L12: 88 | M12: 88
F13: =ROW()-3 | G13: 林 强 | H13: 2 | I13: 86.37 | J13: B | K13: A | L13: 88 | M13: 88
F14: =ROW()-3 | G14: 陈胜华 | H14: 2 | I14: 89.05 | J14: B | K14: B | L14: 88 | M14: 88
F15: =ROW()-3 | G15: 李缘媛 | H15: 2 | I15: 90.16 | J15: B | K15: B | L15: 88 | M15: 88
F16: =ROW()-3 | G16: 陈起颂 | H16: 6 | I16: 87.52 | J16: B | K16: A | L16: 87 | M16: 87
F17: =ROW()-3 | G17: 薛来煌 | H17: 6 | I17: 84.12 | J17: B | K17: B | L17: 87 | M17: 87
F18: =ROW()-3 | G18: 陈 泽 | H18: 6 | I18: 88.59 | J18: B | K18: B | L18: 87 | M18: 87
F19: =ROW()-3 | G19: 陈秀榕 | H19: 6 | I19: 88.93 | J19: B | K19: B | L19: 87 | M19: 87
F20: =ROW()-3 | G20: 林鹏飞 | H20: 10 | I20: 86.46 | J20: B | K20: B | L20: 86 | M20: 86
F21: =ROW()-3 | G21: 盖程伊 | H21: 10 | I21: 87.58 | J21: B | K21: B | L21: 86 | M21: 86
F22: =ROW()-3 | G22: 王 晖 | H22: 10 | I22: 84.05 | J22: B | K22: B | L22: 86 | M22: 86
F23: =ROW()-3 | G23: 林 功 | H23: 13 | I23: 85.11 | J23: B | K23: B | L23: 85 | M23: 85
F24: =ROW()-3 | G24: 许仁捷 | H24: 13 | I24: 84.65 | J24: B | K24: B | L24: 85 | M24: 85
A25: 综合办公室 | B25: =部门绩效考核!E7 | C25: =部门绩效考核!E4 | D25: =部门绩效考核!E5 | E25: =部门绩效考核!E6 | F25: =ROW()-3 | G25: 阮 薇 | H25: 1 | I25: 88.47 | J25: B | K25: B | L25: 91 | M25: 89
F26: =ROW()-3 | G26: 黄 敏 | H26: 2 | I26: 91.78 | J26: A | K26: A | L26: 90 | M26: 88
F27: =ROW()-3 | G27: 郭晓惠 | H27: 3 | I27: 87.42 | J27: B | K27: B | L27: 89 | M27: 87
F28: =ROW()-3 | G28: 潘朝亮 | H28: 3 | I28: 89.69 | J28: B | K28: B | L28: 89 | M28: 87
F29: =ROW()-3 | G29: 江 华 | H29: 5 | I29: 90.21 | J29: B | K29: B | L29: 88 | M29: 87
F30: =ROW()-3 | G30: 高鹤鸣 | H30: 6 | I30: 86.62 | J30: B | K30: B | L30: 88 | M30: 86
F31: =ROW()-3 | G31: 蒋菲菲 | H31: 7 | I31: 85.25 | J31: B | K31: B | L31: 87 | M31: 85
A32: 投资拓展部 | B32: =部门绩效考核!F7 | C32: =部门绩效考核!F4 | D32: =部门绩效考核!F5 | E32: =部门绩效考核!F6 | F32: =ROW()-3 | G32: 陈心亮 | H32: 1 | I32: 87.93 | J32: A | K32: A | L32: 89 | M32: 89
F33: =ROW()-3 | G33: 张彬倩 | H33: 1 | I33: 86.63 | J33: B | K33: B | L33: 89 | M33: 89
F34: =ROW()-3 | G34: 胡世伟 | H34: 3 | I34: 84.96 | J34: B | K34: B | L34: 87 | M34: 87
F35: =ROW()-3 | G35: 鲜卓曦 | H35: 4 | I35: 85.47 | J35: B | K35: B | L35: 86 | M35: 86
A36: 项目管理部 | B36: 张云旭 | C36: =部门绩效考核!G4 | D36: =部门绩效考核!G5 | E36: =部门绩效考核!G6 | F36: =ROW()-3 | G36: 郑春鑫 | H36: 1 | I36: 89.97 | J36: B | K36: A | L36: 90 | M36: 90
F37: =ROW()-3 | G37: 陈世杰 | H37: 2 | I37: 89.98 | J37: B | K37: B | L37: 89 | M37: 89
F38: =ROW()-3 | G38: 林敬楠 | H38: 3 | I38: 88 | J38: B | K38: B | L38: 88 | M38: 89
F39: =ROW()-3 | G39: 兰 枫 | H39: 3 | I39: 90.16 | J39: A | K39: B | L39: 88 | M39: 89
F40: =ROW()-3 | G40: 林奇星 | H40: 5 | I40: 84.82 | J40: B | K40: B | L40: 87 | M40: 88
...

Sheet 绩效考核参照表
A1: 绩效考核人数参照表
A2: 考核 | C2: 部门考核为A | E2: 部门考核为B | G2: 部门考核为C | J2: 部门考核为D
A3: 部门 | B3: 人数 | C3: A比例 30% | D3: BCD比例 70% | E3: A比例 10% | F3: BCD比例 90% | G3: A比例 0% | H3: B比例 80% | I3: CD比例 20%且不少于2人 | J3: A比例 0% | K3: B比例 80% | L3: CD比例 20%且不少于2人
A4: 财务部 | B4: 4 | C4: =B4*0.3 | D4: =B4*0.7 | E4: =B4*0.1 | F4: =B4*0.9 | G4: 0 | H4: =B4-I4 | I4: 2 | J4: 0 | K4: =B4-L4 | L4: 2
A5: 党群纪检审计部 | B5: 4 | C5: =B5*0.3 | D5: =B5*0.7 | E5: =B5*0.1 | F5: =B5*0.9 | G5: 0 | H5: =B5-I5 | I5: 2 | J5: 0 | K5: =B5-L5 | L5: 2
A6: 综合办公室 | B6: 7 | C6: =B6*0.3 | D6: =B6*0.7 | E6: =B6*0.1 | F6: =B6*0.9 | G6: 0 | H6: 5 | I6: 2 | J6: 0 | K6: 5 | L6: 2
A7: 质量安全部 | B7: 4 | C7: =B7*0.3 | D7: =B7*0.7 | E7: =B7*0.1 | F7: =B7*0.9 | G7: 0 | H7: =B7-I7 | I7: 2 | J7: 0 | K7: =B7-L7 | L7: 2
A8: 设计管理部 | B8: 3 | C8: =B8*0.3 | D8: =B8*0.7 | E8: =B8*0.1 | F8: =B8*0.9 | G8: 0 | H8: 1 | I8: 2 | J8: 0 | K8: =B8-L8 | L8: 2
A9: 投资拓展部 | B9: 4 | C9: =B9*0.3 | D9: =B9*0.7 | E9: =B9*0.1 | F9: =B9*0.9 | G9: 0 | H9: 2 | I9: 2 | J9: 0 | K9: 2 | L9: 2
A10: 造价合约部 | B10: 3 | C10: =B10*0.3 | D10: =B10*0.7 | E10: =B10*0.1 | F10: =B10*0.9 | G10: 0 | H10: 1 | I10: 2 | J10: 0 | K10: 1 | L10: 2
A11: 资产管理部 | B11: 8 | C11: =B11*0.3 | D11: =B11*0.7 | E11: =B11*0.1 | F11: =B11*0.9 | G11: 0 | H11: 6 | I11: 2 | J11: 0 | K11: 6 | L11: 2
A12: 项目管理部 | B12: 9 | C12: =B12*0.3 | D12: =B12*0.7 | E12: =B12*0.1 | F12: =B12*0.9 | G12: 0 | H12: =B12-I12 | I12: 2 | J12: 0 | K12: =B12-L12 | L12: 2
A13: 高新区分公司 | B13: 14 | C13: =B13*0.3 | D13: =B13*0.7 | E13: =B13*0.1 | F13: =B13*0.9 | G13: 0 | H13: =B13-I13 | I13: =B13*0.2 | J13: 0 | K13: =B13-L13 | L13: =B13*0.2
A14: 物业分公司 | B14: 6 | C14: =B14*0.3 | D14: =B14*0.7 | E14: =B14*0.1 | F14: =B14*0.9 | G14: 0 | H14: =B14-I14 | I14: 2 | J14: 0 | K14: =B14-L14 | L14: 2

Sheet 公示部门
A1: 部门2026年2月考评情况汇总表
A2: 序号 | B2: 部门 | C2: 综合评定
A3: 1 | B3: 高新区分公司
A4: 2 | B4: 物业分公司
A5: 3 | B5: 设计管理部
A6: 4 | B6: 项目管理部
A7: 5 | B7: 质量安全部
A8: 6 | B8: 资产管理部
A9: 7 | B9: 造价合约部
A10: 8 | B10: 投资拓展部
A11: 9 | B11: 财 务 部
A12: 10 | B12: 党群纪检审计部
A13: 11 | B13: 综合办公室
A14: 绩效考核委员会意见：

Sheet 公示员工1
A1: 一线干部考察2026年2月考评情况汇总表
A2: 部 门 | B2: 序号 | C2: 姓 名 | D2: 职 务 | E2: 综合评定结果
A3: 总经理助理 | B3: 1 | C3: 张云旭 | D3: 总助 项目管理部经理
A4: 高新区分公司 | B4: 1 | C4: 郑石斌 | D4: 负 责 人
B5: 2 | C5: 孙安娜 | D5: 副 职
B6: 3 | C6: 陈南钟 | D6: 职 员
B7: 4 | C7: 林 强 | D7: 职 员
B8: 5 | C8: 林 功 | D8: 职 员
B9: 6 | C9: 王 晖 | D9: 职 员
B10: 7 | C10: 高 彬 | D10: 职 员
B11: 8 | C11: 陈秀榕 | D11: 职 员
B12: 9 | C12: 陈胜华 | D12: 职 员
B13: 10 | C13: 许仁捷 | D13: 职 员
B14: 11 | C14: 薛来煌 | D14: 职 员
B15: 12 | C15: 陈起颂 | D15: 职 员
B16: 13 | C16: 林鹏飞 | D16: 职 员
... B19: 16 | C19: 李缘媛 | D19: 职 员
A20: 物业分公司 | B20: 1 | C20: 陈朝炜 | D20: 负 责 人
B21: 2 | C21: 陈 媛 | D21: 副 职
B22: 3 | C22: 林晓燕 | D22: 职 员
B23: 4 | C23: 林小森 | D23: 职 员
B24: 5 | C24: 肖炜萍 | D24: 职 员
B25: 6 | C25: 林大江 | D25: 职 员
B26: 7 | C26: 王子妍 | D26: 职 员
B27: 8 | C27: 钱 源 | D27: 职 员
A28: 项目管理部 | B28: 1 | C28: 蔡震空 | D28: 副 职
B29: 2 | C29: 林敬楠 | D29: 职 员
B30: 3 | C30: 林奇星 | D30: 职 员
B31: 4 | C31: 郑春鑫 | D31: 职 员
B32: 5 | C32: 兰 枫 | D32: 职 员
B33: 6 | C33: 黄 杰 | D33: 职 员
B34: 7 | C34: 鲍长杰 | D34: 职 员
B35: 8 | C35: 陈世杰 | D35: 职 员
B36: 9 | C36: 邓 越 | D36: 职 员
B37: 10 | C37: 李柏洋 | D37: 职 员
A38: 设计管理部 | B38: 1 | C38: 刘德清 | D38: 负 责 人
B39: 2 | C39: 郑长健 | D39: 职 员
B40: 3 | C40: 谭 圆 | D40: 职 员
B41: 4 | C41: 赵朕昕 | D41: 职 员
A42: 质量安全部 | B42: 1 | C42: 朱晓东 | D42: 负 责 人
...

Sheet 公式员工2
A1: 一线干部考察2026年2月考评情况汇总表
A2: 部 门 | B2: 序号 | C2: 姓 名 | D2: 职 务 | E2: 综合评定结果
A3: 资产管理部 | B3: 1 | C3: 叶 炫 | D3: 负 责 人
B4: 2 | C4: 郑 思 | D4: 职 员
B5: 3 | C5: 李晨飞 | D5: 职 员
B6: 4 | C6: 吴诗翌 | D6: 职 员
B7: 5 | C7: 郑浠冰 | D7: 职 员
B8: 6 | C8: 朱 飞 | D8: 职 员
B9: 7 | C9: 卓 喆 | D9: 职 员
B10: 8 | C10: 林丽英 | D10: 职 员
B11: 9 | C11: 林文志 | D11: 职 员
A12: 造价合约部 | B12: 1 | C12: 陈 杰 | D12: 副 职
B13: 2 | C13: 陈 颖 | D13: 职 员
B14: 3 | C14: 陈文君 | D14: 职 员
B15: 4 | C15: 华海金 | D15: 职 员
A16: 投资拓展部 | B16: 1 | C16: 张旻菲 | D16: 负 责 人
B17: 2 | C17: 陈晔龙 | D17: 副 职
B18: 3 | C18: 鲜卓曦 | D18: 职 员
B19: 4 | C19: 胡世伟 | D19: 职 员
B20: 5 | C20: 陈心亮 | D20: 职 员
B21: 6 | C21: 张彬倩 | D21: 职 员
A22: 财 务 部 | B22: 1 | C22: 陈玲巧 | D22: 负 责 人
B23: 2 | C23: 庄萍萍 | D23: 职 员
B24: 3 | C24: 林 萱 | D24: 职 员
B25: 4 | C25: 魏 琳 | D25: 职 员
A26: 综合办公室 | B26: 1 | C26: 吴华珊 | D26: 负 责 人
B27: 2 | C27: 胡彩仙 | D27: 副 职
B28: 3 | C28: 蒋菲菲 | D28: 职 员
B29: 4 | C29: 江 华 | D29: 职 员
B30: 5 | C30: 高鹤鸣 | D30: 职 员
B31: 6 | C31: 黄 敏 | D31: 职 员
B32: 7 | C32: 阮 薇 | D32: 职 员
B33: 8 | C33: 郭晓惠 | D33: 职 员
B34: 9 | C34: 潘朝亮 | D34: 职 员
A35: 党群纪检审计部 | B35: 1 | C35: 龚心怡 | D35: 负 责 人
B36: 2 | C36: 陈佳欐 | D36: 职 员
B37: 3 | C37: 刘 燕 | D37: 职 员
B38: 4 | C38: 张 琪 | D38: 职 员
B39: 5 | C39: 仇静凯 | D39: 职 员
B40: 6 | C40: 陈宗钰 | D40: 职 员
...
